Workbook
Name _C: #REF!,#REF!,#REF!,#REF!
Name A: #REF!,#REF!,#REF!
Name Ablauf_Zinsbindung_ERP_Ost: [1]Eingabeblatt_Finanzierung!$H$49
Name Ablauf_Zinsbindung_ERP_West: [1]Eingabeblatt_Finanzierung!$D$49
Name Ablauf_Zinsbindung_KfW_Umwelt: [1]Eingabeblatt_Finanzierung!$L$49
Name aktuelles_Jahr: #REF!
Name Anschlusszinssatz_ERP_Ost: [1]Eingabeblatt_Finanzierung!$H$50
Name Anschlusszinssatz_ERP_West: [1]Eingabeblatt_Finanzierung!$D$50
Name Anschlusszinssatz_KfW: [1]Eingabeblatt_Finanzierung!$L$50
Name Anzahl_Projekte: [1]Eingabeblatt_Wirtschaft!$F$69
Name B: #REF!,#REF!,#REF!,#REF!
Name BAB: 0
Name BABNummern: 0
Name Bankfinanzierung: #REF!
Name Beginn_Fondsverwaltung: [1]Eingabeblatt_Wirtschaft!$F$50
Name Beginn_Pacht_Bad_Arolsen: [1]Eingabeblatt_Wirtschaft!$J$48
Name Beginn_Pacht_GVZ_Leipzig: [1]Eingabeblatt_Wirtschaft!$I$48
Name Beginn_Pacht_Langelsheim: [1]Eingabeblatt_Wirtschaft!$H$48
Name Beginn_Pacht_Niedersachsenpark: [1]Eingabeblatt_Wirtschaft!$K$48
Name Beginn_Pacht_Niesky: [1]Eingabeblatt_Wirtschaft!$L$48
Name Beginn_Pacht_Steinau: [1]Eingabeblatt_Wirtschaft!$M$48
Name Betreib_Wartung: '[2]WA light CW1800-500'!$B$36
Name Betreibs_Wartungskosten: [3]Teilberechnungen!#REF!
Name Betrieb_Wartung: '[2]WA light CW1800-500'!$H$19
Name Betriebsbeginn_Bad_Arolsen: YEAR([1]Eingabeblatt_Wirtschaft!$J$10)
Name Betriebsbeginn_GVZ_Leipzig: YEAR([1]Eingabeblatt_Wirtschaft!$I$10)
Name Betriebsbeginn_Langelsheim: YEAR([1]Eingabeblatt_Wirtschaft!$H$10)
Name Betriebsbeginn_Niedersachsenpark: YEAR([1]Eingabeblatt_Wirtschaft!$K$10)
Name Betriebsbeginn_Niesky: YEAR([1]Eingabeblatt_Wirtschaft!$L$10)
Name Betriebsbeginn_Steinau: YEAR([1]Eingabeblatt_Wirtschaft!$M$10)
Name Betriebsstunden: '[2]WA light CW1800-500'!$F$7
Name Brennstoff: '[2]WA light CW1800-500'!$B$35
Name Brennstoffkosten: '[2]WA light CW1800-500'!$H$15
Name Brennstoffleistung: '[2]WA light CW1800-500'!$D$7
Name BVTB: [4]B!$C$6:$AO$18,[4]B!$C$22:$AO$27,[4]B!$C$33:$AO$53
Name BVTF: [4]F!$C$6:$AA$18,[4]F!$C$22:$AA$27,[4]F!$C$33:$AA$53
Name BVTI: [4]I!$C$6:$W$18,[4]I!$C$22:$W$27,[4]I!$C$33:$W$53
Name BVTL: [4]L!$C$6:$C$18,[4]L!$C$22:$C$27,[4]L!$C$33:$C$53
Name BVTT: [4]BVTT!$C$6:$AF$18,[4]BVTT!$C$22:$AF$27,[4]BVTT!$C$33:$AF$53
Name CashFlow: '[2]WA light CW1800-500'!$G$31
Name D: #REF!,#REF!,#REF!
Name DD_EK: #REF!
Name Dess: [4]D!$C$6:$D$18,[4]D!$C$22:$D$27,[4]D!$C$33:$D$53
Name dollar: #REF!
Name DRUCKBEREICH_MI: '[4]G&V'!#REF!
Name E: #REF!,#REF!,#REF!,#REF!
Name Eigenkapital: '[1]Invest. und Finanz.'!$M$33
Name Eigenmittel: '[2]WA light CW1800-500'!$B$18
Name Einzelprojekt: [1]Eingabeblatt_Wirtschaft!$F$71:$F$76
Name EK: #REF!
Name Erlöse_Strom_Bad_Arolsen: #REF!*#REF!*#REF!
Name Erlöse_Strom_GVZ_Leipzig: #REF!*#REF!*#REF!
Name Erlöse_Strom_Langelsheim: #REF!*#REF!*#REF!
Name Erlöse_Strom_Niedersachsenpark: #REF!*#REF!*#REF!
Name Erlöse_Strom_Niesky: #REF!*#REF!*#REF!
Name Erlöse_Strom_Steinau: #REF!*#REF!*#REF!
Name Erlöse_Wärme_Bad_Arolsen: (#REF!*#REF!*#REF!)+(#REF!*#REF!*#REF!)+(#REF!*#REF!*#REF!)
Name Erlöse_Wärme_GVZ_Leipzig: (#REF!*#REF!*#REF!)+(#REF!*#REF!*#REF!)+(#REF!*#REF!*#REF!)
Name Erlöse_Wärme_Langelsheim: (#REF!*#REF!*#REF!)+(#REF!*#REF!*#REF!)+(#REF!*#REF!*#REF!)
Name Erlöse_Wärme_Niedersachsenpark: (#REF!*#REF!*#REF!)+(#REF!*#REF!*#REF!)+(#REF!*#REF!*#REF!)

Sheet Zugelassene Speditionen
A2: INSEKTIVO
A3: Rückverfolgbarkeit: zugelassene Speditionen
A5: Stand: | B5: 46085 | C5: QS-ID: | G5: Gesetzlicher Vertreter: | H5: Helmut Hoffmann
A6: Bezeichnung des hergestellten Futtermittels: | B6: Larven der schwarzen Soldatenfliege, lebend | C6: Standort-Nummer: | G6: Krisenmanager: | H6: Helmut Hoffmann
A9: Daten zum transportierten Futtermittel | C9: Daten zur Spedition
A10: Bezeichnung des Futtermittels | B10: Produktart | C10: Name (Firma und Rechtsform) | D10: Straße, Hausnr. | E10: PLZ | F10: Ort | G10: Ansprechpartner | H10: Telefon | I10: E-Mail | J10: Zertifizierungs-system | K10: QS-ID | L10: Zertifikat gültig bis
A11: Larven der schwarzen Soldatenfliege (lebend) | B11: Einzelfuttermittel | J11: GMP+

Sheet Zugelassene Lieferanten
A2: INSEKTIVO
A3: Rückverfolgbarkeit: zugelassene Lieferanten
A5: Stand: | B5: 46085 | C5: QS-ID: | H5: Gesetzlicher Vertreter: | I5: Helmut Hoffmann
A6: Bezeichnung des hergestellten Futtermittels: | B6: Larven der schwarzen Soldatenfliege, lebend | C6: Standort-Nummer: | H6: Krisenmanager: | I6: Helmut Hoffmann
A9: Daten zum Futtermittel | C9: Daten zum Lieferanten
A10: Bezeichnung des Futtermittels | B10: Produktart | C10: Name (Firma und Rechtsform) | D10: Produktionsart | E10: Straße, Hausnr. | F10: PLZ | G10: Ort | H10: Ansprechpartner | I10: Telefon | J10: E-Mail | K10: Zertifizierungs-system | L10: QS-ID | M10: Standortnummer | N10: Zertifikat gültig bis
A11: Larven der schwarzen Soldatenfliege (lebend) | B11: Einzelfuttermittel | C11: Aue Manfred | D11: Kleinsterzeuger | E11: Spitzöd 1 | F11: 94081 | G11: Fürstenzell | H11: Manfred Aue | I11: 10.872123 | J11: info@aue-spitzoed.de | K11: QS | L11: 4953113280718 | M11: KE00001086 (73) | N11: 46800

Sheet Informationen zu Lieferanten
A1: INSEKTIVO
A2: Rückverfolgbarkeit: Informationen zu Lieferanten der betroffenen Futtermittel
A4: Stand: | B4: 46085 | G4: QS-ID:
A5: Bezeichnung des hergestellten Futtermittels: | B5: Larven der schwarzen Soldatenfliege, lebend | G5: Standort-Nummer:
A7: Daten zum Futtermittel
A8: Bezeichnung des Futtermittels | B8: Lieferant | C8: Produktart | D8: Lieferart | E8: Gelieferte Menge | F8: Lieferdatum | G8: Lieferscheinnummer | H8: Chargennummer/ Batch | I8: Endbestand verkauft am | J8: Lieferantenbewertung (Benotungssystem 1 - 6)
A9: Larven der schwarzen Soldatenfliege | B9: Manfred Aue | C9: Einzelfuttermittel | D9: Spedition NAME

Sheet Informationen zu Kunden
A2: INSEKTIVO
A3: Rückverfolgbarkeit: Informationen zu Kunden der betroffenen Ware
A5: Stand: | B5: 46085 | F5: QS-ID: | K5: Gesetzlicher Vertreter: | L5: Helmut Hoffmann
A6: Bezeichnung des hergestellten Futtermittels: | B6: Larven der schwarzen Soldatenfliege, lebend | F6: Standort-Nummer: | K6: Krisenmanager: | L6: Helmut Hoffmann
A9: Daten zum Kunden
A10: Name (Firma und Rechtsform) | B10: Produktionsart | C10: Straße, Hausnr. | D10: PLZ | E10: Ort | F10: Telefon | G10: E-Mail | H10: Betriebsnummer | I10: Zertifizierungssystem | J10: QS-ID | K10: betroffene Charge
A11: Fam. Manfred Aue | B11: Landwirtschaft | C11: Spitzöd 1 | D11: 94081 | E11: Spitzöd | F11: 08502/782 | G11: info@aue-spitzoed.de | H11: 092751220010 | I11: QS | J11: 4031735448580

Sheet Rückverfolgbarkeitsprobe Liefer
A2: INSEKTIVO
A3: Rückverfolgungsvorgang: Rückruf durch Lieferanten
A5: Stand: | C5: 45581
A6: Bezeichnung des hergestellten Futtermittels: | C6: Larven der schwarzen Soldatenfliege, lebend
A8: QS-ID:
A9: Standort-Nummer:
A11: Gesetzlicher Vertreter: | C11: Helmut Hoffmann
A12: Krisenmanager: | C12: Helmut Hoffmann
A14: Szenario: Lieferant meldet Problem mit Ausgangsstoff
A15: Nr. | B15: Bezeichnung des Schrittes | C15: Durchzuführende Maßnahmen | D15: Ergebnis | E15: Uhrzeit
A16: 1 | B16: Eingang des Rückrufes | C16: Dokumentation des Rückrufes : Grund für den Rückruf, Betroffene Rohstoffe, Chargennummer, Lieferdatum, gelieferte Menge
A17: 2 | B17: Wurde die betroffene Ware eingesetzt? | C17: Es muss geprüft werden, ob die betroffenen Chargen an Futtermitteln bereits angebrochen wurden. Dafür wird im Formblatt "Rückverfolgbarkeit: Informationen zu Lieferanten der betroffenen Futtermittel" überprüft, ob das Namensgleiche Futtermittel der zuvor gelieferten Charge bereits aufgebraucht ist. Ist dieses noch nicht aufgebraucht kann Entwarnung gegeben werden, da dann die betroffene Charge noch nicht eingesetzt wurde. Ware noch nicht eingesetzt -> Entwarnung Ware bereits angebrochen oder aufgebraucht -> Weitere Rückverfolgung
A18: 3 | B18: Meldung an QS | C18: Wurde die zrückgerufene Ware bereits eingesetzt, muss QS unverzüglich informiert werden.
A19: 4 | B19: Ermittlung des Produktionsdatum /Chargennummer | C19: Anhand des Eingangs und des Aufbrauchsdatum des Zurückgerufenen Produktes und Programm des Futtermischers müssen alle Chargennummern der Insektenlarven herausgefunden werden, die mit dem fehlerhaften Futtermittel gefüttert worden sind.
A20: 5 | B20: Betroffene Ware bereits verkauft? | C20: Mit dem Formblatt "Rückverfolgbarkeit: Informationen zu Kunden der betroffenen Ware" muss herausgefunden werden, ob die Larven, welche mit dem fehlerhaften Futtermittel gefüttert wurden, bereits verkauft wurden. Ist die gesamte Ware oder ein Teil der Ware noch nicht verkauft, so muss ein Verkauf sofort unterbunden und die betroffene Ware gegebenenfalls vernichtet werden. Ist die betroffene Ware bereits komplett oder auch nur zum Teil verkauft, so ist eine weitere Rückverfolgung mit den nächsten Schritten notwendig.
A21: 6 | B21: Ermittlung der Kunden, die betroffen Ware erhalten haben | C21: Anhand dem Formblatt "Rückverfolgbarkeit: Informationen zu Kunden der betroffenen Ware" und der betroffenen Chargennummern müssen die Kontaktdaten der Kunden, die bereits betroffene Ware erhalten haben ermittelt und für QS verarbeitbar aufbereitet werden.
A22: 7 | B22: Information der Kunden | C22: Die Betroffenen Kunden müssen unverzüglich darüber informiert werden, dass unser Produkt mit einem fehlerhaften Ausgangsstoff hergestellt wurde, damit diese die Verwendung verhindern beziehungsweise einstellen können.
A23: 8 | B23: Weiterleitung an QS | C23: Die Aufbereiteten Daten müssen an QS übermittelt werden
A24: 9

Sheet Rückverfolgbarkeitsprobe Kunde
A2: INSEKTIVO
A3: Rückverfolgungsvorgang: Reklamation vom Kunden
A5: Stand: | C5: 46085
A6: Bezeichnung des hergestellten Futtermittels: | C6: Larven der schwarzen Soldatenfliege, lebend
A8: QS-ID:
A9: Standort-Nummer:
A11: Gesetzlicher Vertreter: | C11: Helmut Hoffmann
A12: Krisenmanager: | C12: Helmut Hoffmann
A14: Szenario: Kunde meldet Problem mit Produkt
A15: Nr. | B15: Bezeichnung des Schrittes | C15: Durchzuführende Maßnahmen | D15: Ergebnis | E15: Uhrzeit
A16: 1 | B16: Eingang der Reklamation | C16: Dokumentation der eingehenden Reklamation
A17: 2 | B17: Sind wir Verursacher? | C17: Es muss geprüft werden, ob unser Produkt für die beim Kunden auftretenden Probelme verantwortlich sein kann. Wenn Ja -> Weitere Rückverfolgung Wenn Nein -> Rückverfolgung abgeschlossen
A18: 3 | B18: Meldung an QS | C18: Das Problem, welches eventuell von unserem Produkt stammen könnte, muss unverzüglich QS mitgeteilt werden.
A19: 4 | B19: Ermittlung des Produktionsdatum /Chargennummer | C19: Beim Kunden muss nach dem Produktionsdatum und der Chargennummer der Ware, die für den Schaden verantwortlich ist, abgefragt werden
A20: 5 | B20: Ermittlung weiter eventuell betroffener Kunden | C20: Mit dem Formblatt "Rückverfolgbarkeit: Informationen zu Kunden der betroffenen Ware" Müssen alle Kunden ermittelt werden, welche Larven mit der gleichen Charge, wie der reklamierende Kunde erhalten haben. Nach der Ermittlung der Kontaktdaten dieser Abnehmer müssen diese unmittelbar darüber informiert werden, dass möglicherweise ein Problem mit der von uns ausgelieferten Ware vorliegt, damit diese eine Verwendung verhindern, beziehungseise eine weitere Verwendung unterbinden können.
A21: 6 | B21: Ermittlung der Futterrezeptur der Charge | C21: Im System des Futtermischers muss die genaue Rezeptur und somit die eingesetzten Futtermittel in der Betroffenen Charge herausgesucht werden.
A22: 7 | B22: Festlegung der Chargen der Futtermittel in der Futterrezeptur | C22: Anhand des Formblattes "Rückverfolgbarkeit: Informationen zu Lieferanten der betroffenen Futtermittel" und dem Herstellungsdatum müssen die betroffenen Chargen der eingesetzten Futtermittel bestimmt werden. Dabei ist jeweils die Charge eingesetzt worden, bei der das Datum für den Wareneingang und das Datum des Aufbrauchs der Charge den Zeitraum der Produktion des fehlerhaften Produktes umschließen. Es sei denn das Produktionsdatum liegt in einem Zeitraum, an dem 2 verschiedene Chargen eines Futtermittels auf dem Betriebsgelände waren. Ist dies der Fall, so ist immer die angebrochene Charge die Betroffene.
A23: 8 | B23: Bestimmung der Lieferanten der Betroffenen Ausgangsstoffe | C23: Anhand des Formblattes "Rückverfolgbarkeit: Informationen zu Lieferanten der betroffenen Futtermittel" müssen die entsprechenden Daten zu den Lieferanten der betoffenen Futtermittermittel herausgezogen für QS Verarbeitbar aufbereitet werden
A24: 9 | B24: Weiterleitung an QS | C24: Die Aufbereiteten Daten müssen an QS übermittelt werden

Sheet Hilfstabellen
A3: Pyrolyse
A5: Anlagenhersteller und -typ | B5: Brennstoffbedarf [tatro p.a.]2 | C5: Thermische Leistung | D5: Produktion Biokohle [tatro p.a.] | E5: Richtpreis
A6: Biomacon C40-F | B6: 156 | C6: 40 | D6: 37 | I6: =+#REF! -> #REF! | J6: =+#REF! -> #REF!
A7: Biomacon C63-F | B7: 240 | C7: 63 | D7: 57 | I7: =+#REF! -> #REF! | J7: =+#REF! -> #REF!
A8: Biomacon C100-F | B8: 384 | C8: 100 | D8: 92 | E8: 160000
A9: Biomacon C160-F | B9: 608 | C9: 160 | D9: 146
A10: Biomacon C250-I | B10: 944 | C10: 250 | D10: 256
A11: Biomacon C400-I | B11: 1520 | C11: 400 | D11: 364 | I11: =+#REF! -> #REF! | J11: =+#REF! -> #REF!
A12: Biomacon C500-I | B12: 1888 | C12: 500 | D12: 453
I14: =+#REF! -> #REF! | J14: =+#REF! -> #REF!
C15: Erträge | D15: Aufwendungen
C16: =+#REF! -> #REF! | D16: =+#REF! -> #REF! | I16: =+#REF! -> #REF! | J16: =+#REF! -> #REF!
I17: Energie, Wasser | J17: =+#REF!+#REF! -> #REF!
I18: =+#REF! -> #REF! | J18: =+#REF! -> #REF!
I19: =+#REF! -> #REF! | J19: =+#REF! -> #REF!
I20: Sonstiger Betrieblicher Aufwand | J20: =SUM(#REF!) -> #REF!
I24: =+#REF! -> #REF! | J24: =+#REF! -> #REF!

Sheet G&V
A2: Projekt: | C2: =+#REF! -> #REF! | I2: Stand: | J2: =+#REF! -> #REF!
A5: 6. Gewinn und Verlustrechnung | I5: =+#REF! -> #REF! | J5: =+#REF! -> #REF! | K5: =J5+1 -> #REF! | L5: =K5+1 -> #REF! | M5: =L5+1 -> #REF! | N5: =M5+1 -> #REF! | O5: =N5+1 -> #REF! | P5: =O5+1 -> #REF! | Q5: =P5+1 -> #REF! | R5: =Q5+1 -> #REF! | ... X5: =W5+1 -> #REF! | Y5: =#REF!+1 -> #REF!
I6: =H6+1 -> 1 | J6: 1 | K6: =J6+1 -> 2 | L6: =K6+1 -> 3 | M6: =L6+1 -> 4 | N6: =M6+1 -> 5 | O6: =N6+1 -> 6 | P6: =O6+1 -> 7 | Q6: =P6+1 -> 8 | R6: =Q6+1 -> 9 | ... X6: =W6+1 -> 15 | Y6: =#REF!+1 -> #REF!
B7: Umsatz Insekten | I7: =+#REF! -> #REF! | J7: =+#REF! -> #REF! | K7: =+J7 -> #REF! | L7: =+K7 -> #REF! | M7: =+L7 -> #REF! | N7: =+M7 -> #REF! | O7: =+N7 -> #REF! | P7: =+O7 -> #REF! | Q7: =+P7 -> #REF! | R7: =+Q7 -> #REF! | ... Y7: =+X7 -> #REF!
B8: Umsatz Dünger | I8: =+#REF! -> #REF! | J8: =+#REF! -> #REF! | K8: =+J8 -> #REF! | L8: =+K8 -> #REF! | M8: =+L8 -> #REF! | N8: =+M8 -> #REF! | O8: =+N8 -> #REF! | P8: =+O8 -> #REF! | Q8: =+P8 -> #REF! | R8: =+Q8 -> #REF! | ... Y8: =+X8 -> #REF!
B9: Umsatz Biokohlen | I9: =+#REF! -> #REF! | J9: =+#REF! -> #REF! | K9: =+J9 -> #REF! | L9: =+K9 -> #REF! | M9: =+L9 -> #REF! | N9: =+M9 -> #REF! | O9: =+N9 -> #REF! | P9: =+O9 -> #REF! | Q9: =+P9 -> #REF! | R9: =+Q9 -> #REF! | ... Y9: =+X9 -> #REF!
B10: Umsatz CO2 Zertifikate | J10: =+#REF! -> #REF! | K10: =+J10 -> #REF! | L10: =+K10 -> #REF! | M10: =+L10 -> #REF! | N10: =+M10 -> #REF! | O10: =+N10 -> #REF! | P10: =+O10 -> #REF! | Q10: =+P10 -> #REF! | R10: =+Q10 -> #REF! | ... Y10: =+X10 -> #REF!
B11: Umsatz Wärmeverkauf | J11: =+#REF! -> #REF! | K11: =+J11 -> #REF! | L11: =+K11 -> #REF! | M11: =+L11 -> #REF! | N11: =+M11 -> #REF! | O11: =+N11 -> #REF! | P11: =+O11 -> #REF! | Q11: =+P11 -> #REF! | R11: =+Q11 -> #REF! | ... Y11: =+X11 -> #REF!
A12: ð | B12: Umsatzerlöse | I12: =SUM(I7:I9) -> #REF! | J12: =SUM(J7:J11) -> #REF! | K12: =SUM(K7:K11) -> #REF! | L12: =SUM(L7:L11) -> #REF! | M12: =SUM(M7:M11) -> #REF! | N12: =SUM(N7:N11) -> #REF! | O12: =SUM(O7:O11) -> #REF! | P12: =SUM(P7:P11) -> #REF! | Q12: =SUM(Q7:Q11) -> #REF! | ... X12: =SUM(X7:X11) -> #REF! | Y12: =SUM(Y7:Y9) -> #REF!
A14: ð | B14: Sonstiger betrieblicher Ertrag | I14: =SUM(I13:I13) -> 0 | J14: =SUM(J13:J13) -> 0 | K14: =SUM(K13:K13) -> 0 | L14: =SUM(L13:L13) -> 0 | M14: =SUM(M13:M13) -> 0 | N14: =SUM(N13:N13) -> 0 | O14: =SUM(O13:O13) -> 0 | P14: =SUM(P13:P13) -> 0 | ... Y14: =SUM(Y13:Y13) -> 0
B15: Summe der Erträge | I15: =+I12+I14 -> #REF! | J15: =+J12+J14 -> #REF! | K15: =+K12+K14 -> #REF! | L15: =+L12+L14 -> #REF! | M15: =+M12+M14 -> #REF! | N15: =+N12+N14 -> #REF! | O15: =+O12+O14 -> #REF! | P15: =+P12+P14 -> #REF! | ... Y15: =+Y12+Y14 -> #REF!
B17: Kosten Futtermittel | I17: =+#REF! -> #REF! | J17: =+#REF!+#REF!+#REF!+#REF! -> #REF! | K17: =+J17 -> #REF! | L17: =+K17 -> #REF! | M17: =+L17 -> #REF! | N17: =+M17 -> #REF! | O17: =+N17 -> #REF! | P17: =+O17 -> #REF! | Q17: =+P17 -> #REF! | R17: =+Q17 -> #REF! | ... X17: =+W17 -> #REF!
B18: Brennstoff Pyrolyse | J18: =+#REF! -> #REF! | K18: =+J18 -> #REF! | L18: =+K18 -> #REF! | M18: =+L18 -> #REF! | N18: =+M18 -> #REF! | O18: =+N18 -> #REF! | P18: =+O18 -> #REF! | Q18: =+P18 -> #REF! | R18: =+Q18 -> #REF! | ... X18: =+W18 -> #REF!
B19: Junglarven | I19: =+#REF! -> #REF! | J19: =+#REF! -> #REF! | K19: =+J19 -> #REF! | L19: =+K19 -> #REF! | M19: =+L19 -> #REF! | N19: =+M19 -> #REF! | O19: =+N19 -> #REF! | P19: =+O19 -> #REF! | Q19: =+P19 -> #REF! | R19: =+Q19 -> #REF! | ... X19: =+W19 -> #REF!
B20: Energiekosten | I20: =+#REF!+#REF! -> #REF! | J20: =+#REF!+#REF! -> #REF! | K20: =+J20 -> #REF! | L20: =+K20 -> #REF! | M20: =+L20 -> #REF! | N20: =+M20 -> #REF! | O20: =+N20 -> #REF! | P20: =+O20 -> #REF! | Q20: =+P20 -> #REF! | R20: =+Q20 -> #REF! | ... X20: =+W20 -> #REF!
B21: Wasser- und Abwasserkosten | I21: =+#REF! -> #REF! | J21: 5000 | K21: =+J21 -> 5000 | L21: =+K21 -> 5000 | M21: =+L21 -> 5000 | N21: =+M21 -> 5000 | O21: =+N21 -> 5000 | P21: =+O21 -> 5000 | Q21: =+P21 -> 5000 | R21: =+Q21 -> 5000 | ... X21: =+W21 -> 5000
A23: ð | B23: Materialkosten | I23: =SUM(I16:I22) -> #REF! | J23: =SUM(J17:J21) -> #REF! | K23: =SUM(K17:K21) -> #REF! | L23: =SUM(L17:L21) -> #REF! | M23: =SUM(M17:M21) -> #REF! | N23: =SUM(N17:N21) -> #REF! | O23: =SUM(O17:O21) -> #REF! | P23: =SUM(P17:P21) -> #REF! | Q23: =SUM(Q17:Q21) -> #REF! | ... X23: =SUM(X17:X21) -> #REF! | Y23: =SUM(Y16:Y22) -> 0
B24: ROHERTRAG | I24: =+I15-I23 -> #REF! | J24: =+J15-J23 -> #REF! | K24: =+K15-K23 -> #REF! | L24: =+L15-L23 -> #REF! | M24: =+M15-M23 -> #REF! | N24: =+N15-N23 -> #REF! | O24: =+O15-O23 -> #REF! | P24: =+P15-P23 -> #REF! | ... Y24: =+Y15-Y23 -> #REF!
B25: Personal | I25: =+#REF!+#REF!+#REF! -> #REF! | J25: =+#REF! -> #REF! | K25: =+J25 -> #REF! | L25: =+K25 -> #REF! | M25: =+L25 -> #REF! | N25: =+M25 -> #REF! | O25: =+N25 -> #REF! | P25: =+O25 -> #REF! | Q25: =+P25 -> #REF! | R25: =+Q25 -> #REF! | ... X25: =+W25 -> #REF! | Y25: =+#REF! -> #REF!
B26: Abschreibung | I26: =+AfA!N16 -> 0 | J26: =+AfA!O16 -> #REF! | K26: =+AfA!P16 -> #REF! | L26: =+AfA!Q16 -> #REF! | M26: =+AfA!R16 -> #REF! | N26: =+AfA!S16 -> #REF! | O26: =+AfA!T16 -> #REF! | P26: =+AfA!U16 -> #REF! | ... X26: =+AfA!AC16 -> #REF! | Y26: =+AfA!#REF! -> #REF!
B27: Hilfs- und Betriebsstoffe | J27: =+#REF! -> #REF! | K27: =+J27 -> #REF! | L27: =+K27 -> #REF! | M27: =+L27 -> #REF! | N27: =+M27 -> #REF! | O27: =+N27 -> #REF! | P27: =+O27 -> #REF! | Q27: =+P27 -> #REF! | R27: =+Q27 -> #REF! | ... X27: =+W27 -> #REF!
B28: Wartung und Instandhaltung | I28: =+#REF!+#REF! -> #REF! | J28: =+#REF! -> #REF! | K28: =+J28 -> #REF! | L28: =+K28 -> #REF! | M28: =+L28 -> #REF! | N28: =+M28 -> #REF! | O28: =+N28 -> #REF! | P28: =+O28 -> #REF! | Q28: =+P28 -> #REF! | R28: =+Q28 -> #REF! | ... X28: =+W28 -> #REF! | Y28: =+#REF! -> #REF!
B29: Versicherung | I29: =+#REF!+#REF!+#REF! -> #REF! | J29: =+#REF! -> #REF! | K29: =+J29 -> #REF! | L29: =+K29 -> #REF! | M29: =+L29 -> #REF! | N29: =+M29 -> #REF! | O29: =+N29 -> #REF! | P29: =+O29 -> #REF! | Q29: =+P29 -> #REF! | R29: =+Q29 -> #REF! | ... X29: =+W29 -> #REF! | Y29: =+#REF! -> #REF!
A30: ð | B30: Sonstiger betrieblicher Aufwand (SBA) | I30: =SUM(I28:I29) -> #REF! | J30: =SUM(J27:J29) -> #REF! | K30: =SUM(K27:K29) -> #REF! | L30: =SUM(L27:L29) -> #REF! | M30: =SUM(M27:M29) -> #REF! | N30: =SUM(N27:N29) -> #REF! | O30: =SUM(O27:O29) -> #REF! | P30: =SUM(P27:P29) -> #REF! | Q30: =SUM(Q27:Q29) -> #REF! | ... X30: =SUM(X27:X29) -> #REF! | Y30: =SUM(Y28:Y29) -> #REF!
B31: Zinsen für Darlehen | I31: 0 | J31: =+#REF! -> #REF! | K31: =+#REF! -> #REF! | L31: =+#REF! -> #REF! | M31: =+#REF! -> #REF! | N31: =+#REF! -> #REF! | O31: =+#REF! -> #REF! | P31: =+#REF! -> #REF! | Q31: =+#REF! -> #REF! | ... X31: =+#REF! -> #REF! | Y31: =#REF! -> #REF!
A32: ð | B32: Zinsaufwand | I32: =SUM(I31:I31) -> 0 | J32: =SUM(J31:J31) -> #REF! | K32: =SUM(K31:K31) -> #REF! | L32: =SUM(L31:L31) -> #REF! | M32: =SUM(M31:M31) -> #REF! | N32: =SUM(N31:N31) -> #REF! | O32: =SUM(O31:O31) -> #REF! | P32: =SUM(P31:P31) -> #REF! | ... Y32: =SUM(Y31:Y31) -> #REF!
B33: Summe der Aufwendungen | I33: =+I23+#REF!+I30+I32+I26 -> #REF! | J33: =+J23+J25+J26+J30+J32 -> #REF! | K33: =+K23+K25+K26+K30+K32 -> #REF! | L33: =+L23+L25+L26+L30+L32 -> #REF! | M33: =+M23+M25+M26+M30+M32 -> #REF! | N33: =+N23+N25+N26+N30+N32 -> #REF! | O33: =+O23+O25+O26+O30+O32 -> #REF! | P33: =+P23+P25+P26+P30+P32 -> #REF! | Q33: =+Q23+Q25+Q26+Q30+Q32 -> #REF! | ... X33: =+X23+X25+X26+X30+X32 -> #REF! | Y33: =+Y23+#REF!+Y30+Y32+Y26 -> #REF!
B35: Ergebnis der Geschäftstätigkeit (EBT)* | I35: =+I15-I33 -> #REF! | J35: =+J15-J33 -> #REF! | K35: =+K15-K33 -> #REF! | L35: =+L15-L33 -> #REF! | M35: =+M15-M33 -> #REF! | N35: =+N15-N33 -> #REF! | O35: =+O15-O33 -> #REF! | P35: =+P15-P33 -> #REF! | ... Y35: =+Y15-Y33 -> #REF!
B36: Steuer | D36: 0.25 | I36: 0 | J36: =+J35*$D$36 -> #REF! | K36: =+K35*$D$36 -> #REF! | L36: =+L35*$D$36 -> #REF! | M36: =+M35*$D$36 -> #REF! | N36: =+N35*$D$36 -> #REF! | O36: =+O35*$D$36 -> #REF! | P36: =+P35*$D$36 -> #REF! | Q36: =+Q35*$D$36 -> #REF! | ... Y36: =+Y35*$D$36 -> #REF!
B37: Jahresüberschuss | I37: =+I32-#REF! -> #REF! | J37: =+J35-J36 -> #REF! | K37: =+K35-K36 -> #REF! | L37: =+L35-L36 -> #REF! | M37: =+M35-M36 -> #REF! | N37: =+N35-N36 -> #REF! | O37: =+O35-O36 -> #REF! | P37: =+P35-P36 -> #REF! | Q37: =+Q35-Q36 -> #REF! | ... X37: =+X35-X36 -> #REF! | Y37: =+Y32-#REF! -> #REF!
B39: + Abschreibung | J39: =+J26 -> #REF! | K39: =+K26 -> #REF! | L39: =+L26 -> #REF! | M39: =+M26 -> #REF! | N39: =+N26 -> #REF! | O39: =+O26 -> #REF! | P39: =+P26 -> #REF! | Q39: =+Q26 -> #REF! | ... X39: =+X26 -> #REF!
B40: CF1 | J40: =+J37+J39 -> #REF! | K40: =+K37+K39 -> #REF! | L40: =+L37+L39 -> #REF! | M40: =+M37+M39 -> #REF! | N40: =+N37+N39 -> #REF! | O40: =+O37+O39 -> #REF! | P40: =+P37+P39 -> #REF! | Q40: =+Q37+Q39 -> #REF! | ... X40: =+X37+X39 -> #REF!
B41: - Tilgung | J41: =+#REF! -> #REF! | K41: =+#REF! -> #REF! | L41: =+#REF! -> #REF! | M41: =+#REF! -> #REF! | N41: =+#REF! -> #REF! | O41: =+#REF! -> #REF! | P41: =+#REF! -> #REF! | Q41: =+#REF! -> #REF! | ... Y41: =+#REF! -> #REF!
B42: CF2 | J42: =+J40-J41 -> #REF! | K42: =+K40-K41 -> #REF! | L42: =+L40-L41 -> #REF! | M42: =+M40-M41 -> #REF! | N42: =+N40-N41 -> #REF! | O42: =+O40-O41 -> #REF! | P42: =+P40-P41 -> #REF! | Q42: =+Q40-Q41 -> #REF! | ... X42: =+X40-X41 -> #REF!
B46: CF1 vor Zins und Tilgung | J46: =+J40+J31 -> #REF! | K46: =+K40+K31 -> #REF! | L46: =+L40+L31 -> #REF! | M46: =+M40+M31 -> #REF! | N46: =+N40+N31 -> #REF! | O46: =+O40+O31 -> #REF! | P46: =+P40+P31 -> #REF! | Q46: =+Q40+Q31 -> #REF! | ... X46: =+X40+X31 -> #REF!
B49: Kumulierter Cash Flow 1 (vor Zins und Tilgung) | J49: =+J46 -> #REF! | K49: =+J49+K46 -> #REF! | L49: =+K49+L46 -> #REF! | M49: =+L49+M46 -> #REF! | N49: =+M49+N46 -> #REF! | O49: =+N49+O46 -> #REF! | P49: =+O49+P46 -> #REF! | Q49: =+P49+Q46 -> #REF! | R49: =+Q49+R46 -> #REF! | ... X49: =+W49+X46 -> #REF!
B50: Investition | J50: =+#REF! -> #REF! | K50: =+J50 -> #REF! | L50: =+K50 -> #REF! | M50: =+L50 -> #REF! | N50: =+M50 -> #REF! | O50: =+N50 -> #REF! | P50: =+O50 -> #REF! | Q50: =+P50 -> #REF! | R50: =+Q50 -> #REF! | ... X50: =+W50 -> #REF!
B52: Kumulierter Cash Flow 2 (nach Zins und Tilgung) | J52: =+J42 -> #REF! | K52: =+J52+K42 -> #REF! | L52: =+K52+L42 -> #REF! | M52: =+L52+M42 -> #REF! | N52: =+M52+N42 -> #REF! | O52: =+N52+O42 -> #REF! | P52: =+O52+P42 -> #REF! | Q52: =+P52+Q42 -> #REF! | R52: =+Q52+R42 -> #REF! | ... Y52: =+X52+Y42 -> #REF!
B53: Eigenkapital | J53: =+#REF! -> #REF! | K53: =+J53 -> #REF! | L53: =+K53 -> #REF! | M53: =+L53 -> #REF! | N53: =+M53 -> #REF! | O53: =+N53 -> #REF! | P53: =+O53 -> #REF! | Q53: =+P53 -> #REF! | R53: =+Q53 -> #REF! | ... X53: =+W53 -> #REF!
B55: IRR | C55: =IRR(G55:X55) -> #VALUE! | G55: =-J50 -> #REF! | J55: =+J49 -> #REF! | K55: =+K49 -> #REF! | L55: =+L49 -> #REF! | M55: =+M49 -> #REF! | N55: =+N49 -> #REF! | O55: =+O49 -> #REF! | P55: =+P49 -> #REF! | Q55: =+Q49 -> #REF! | ... X55: =+X49 -> #REF!
...

Sheet AfA
C2: Projekt: | D2: =#REF! -> #REF! | J2: Stand: | K2: =#REF! -> #REF! | Q2: Beginn der Abschreibung: | R2: =#REF! -> #REF! | U2: Ende der Abschreibung: | V2: =#REF! -> #REF!
B6: 13. Abschreibung für Anlagen (AfA) | N6: =#REF! -> #REF! | O6: =N6+1 -> #REF! | P6: =O6+1 -> #REF! | Q6: =P6+1 -> #REF! | R6: =Q6+1 -> #REF! | S6: =R6+1 -> #REF! | T6: =S6+1 -> #REF! | U6: =T6+1 -> #REF! | V6: =U6+1 -> #REF! | ... AD6: =AC6+1 -> #REF!
E8: Abschr.- | F8: Nutzungs- | H8: Anschaffungs- | J8: Bemessungsgrundlage | L8: Abweichung Abschr.
E9: art | F9: dauer | H9: kosten | J9: nach Bauherrenerlass | L9: Handelbil. - Steuerbil.
F10: (Jahre) | H10: gesamt | J10: zu aktivierende Kosten | L10: (jährlich)
J11: 0
B12: a.) | C12: Grundstück inkl. Erschließung | E12: linear | F12: 0 | H12: =#REF! -> #REF! | J12: =H12*(1+$J$11) -> #REF! | L12: =IFERROR(ROUND((J12-H12)/F12,0),0) -> 0
B13: b.) | C13: Gebäude | E13: linear | F13: =+#REF! -> #REF! | H13: =+#REF! -> #REF! | J13: =H13*(1+$J$11) -> #REF! | L13: =IFERROR(ROUND((J13-H13)/F13,0),0) -> 0 | O13: =+H13/F13 -> #REF! | P13: =+O13 -> #REF! | Q13: =+P13 -> #REF! | R13: =+Q13 -> #REF! | S13: =+R13 -> #REF! | T13: =+S13 -> #REF! | U13: =+T13 -> #REF! | V13: =+U13 -> #REF! | W13: =+V13 -> #REF! | ... AD13: =+AC13 -> #REF!
B14: c.) | C14: Außenanlagen | E14: linear | F14: =+#REF! -> #REF! | H14: =+#REF! -> #REF! | J14: =H14*(1+$J$11) -> #REF! | L14: =IFERROR(ROUND((J14-H14)/F14,0),0) -> 0 | O14: =+H14/F14 -> #REF! | P14: =+O14 -> #REF! | Q14: =+P14 -> #REF! | R14: =+Q14 -> #REF! | S14: =+R14 -> #REF! | T14: =+S14 -> #REF! | U14: =+T14 -> #REF! | V14: =+U14 -> #REF! | W14: =+V14 -> #REF! | ... AD14: =+AC14 -> #REF!
B15: d.) | C15: Technische Anlagen/Maschinen | E15: linear | F15: =+#REF! -> #REF! | H15: =+#REF! -> #REF! | J15: =H15*(1+$J$11) -> #REF! | L15: =IFERROR(ROUND((J15-H15)/F15,0),0) -> 0 | O15: =+H15/F15 -> #REF! | P15: =+O15 -> #REF! | Q15: =+P15 -> #REF! | R15: =+Q15 -> #REF! | S15: =+R15 -> #REF! | T15: =+S15 -> #REF! | U15: =+T15 -> #REF! | V15: =+U15 -> #REF! | W15: =+V15 -> #REF! | ... AD15: =+AC15 -> #REF!
C16: Jährliche Abschreibung [€/a] | O16: =SUM(O13:O15) -> #REF! | P16: =SUM(P13:P15) -> #REF! | Q16: =SUM(Q13:Q15) -> #REF! | R16: =SUM(R13:R15) -> #REF! | S16: =SUM(S13:S15) -> #REF! | T16: =SUM(T13:T15) -> #REF! | U16: =SUM(U13:U15) -> #REF! | V16: =SUM(V13:V15) -> #REF! | ... AD16: =SUM(AD13:AD15) -> #REF!
